[2025-07-03T09:17:16.416+0000] {taskinstance.py:1956} INFO - Dependencies all met for dep_context=non-requeueable deps ti=<TaskInstance: task_2_dagv01.extract manual__2025-07-03T09:16:33.660418+00:00 [queued]>
[2025-07-03T09:17:16.424+0000] {taskinstance.py:1956} INFO - Dependencies all met for dep_context=requeueable deps ti=<TaskInstance: task_2_dagv01.extract manual__2025-07-03T09:16:33.660418+00:00 [queued]>
[2025-07-03T09:17:16.424+0000] {taskinstance.py:2170} INFO - Starting attempt 2 of 2
[2025-07-03T09:17:16.467+0000] {taskinstance.py:2191} INFO - Executing <Task(PythonOperator): extract> on 2025-07-03 09:16:33.660418+00:00
[2025-07-03T09:17:16.472+0000] {standard_task_runner.py:60} INFO - Started process 298 to run task
[2025-07-03T09:17:16.475+0000] {standard_task_runner.py:87} INFO - Running: ['airflow', 'tasks', 'run', 'task_2_dagv01', 'extract', 'manual__2025-07-03T09:16:33.660418+00:00', '--job-id', '4', '--raw', '--subdir', 'DAGS_FOLDER/task_2_dag.py', '--cfg-path', '/tmp/tmp782i0608']
[2025-07-03T09:17:16.477+0000] {standard_task_runner.py:88} INFO - Job 4: Subtask extract
[2025-07-03T09:17:16.518+0000] {logging_mixin.py:188} WARNING - /home/airflow/.local/lib/python3.8/site-packages/airflow/settings.py:194 DeprecationWarning: The sql_alchemy_conn option in [core] has been moved to the sql_alchemy_conn option in [database] - the old setting has been used, but please update your config.
[2025-07-03T09:17:16.554+0000] {task_command.py:423} INFO - Running <TaskInstance: task_2_dagv01.extract manual__2025-07-03T09:16:33.660418+00:00 [running]> on host b70660b8d774
[2025-07-03T09:17:16.691+0000] {taskinstance.py:2480} INFO - Exporting env vars: AIRFLOW_CTX_DAG_OWNER='airflow' AIRFLOW_CTX_DAG_ID='task_2_dagv01' AIRFLOW_CTX_TASK_ID='extract' AIRFLOW_CTX_EXECUTION_DATE='2025-07-03T09:16:33.660418+00:00' AIRFLOW_CTX_TRY_NUMBER='2' AIRFLOW_CTX_DAG_RUN_ID='manual__2025-07-03T09:16:33.660418+00:00'
[2025-07-03T09:17:16.692+0000] {taskinstance.py:2698} ERROR - Task failed with exception
Traceback (most recent call last):
  File "/home/airflow/.local/lib/python3.8/site-packages/airflow/models/taskinstance.py", line 433, in _execute_task
    result = execute_callable(context=context, **execute_callable_kwargs)
  File "/home/airflow/.local/lib/python3.8/site-packages/airflow/operators/python.py", line 196, in execute
    context_merge(context, self.op_kwargs, templates_dict=self.templates_dict)
  File "/home/airflow/.local/lib/python3.8/site-packages/airflow/utils/context.py", line 261, in context_merge
    context.update(*args, **kwargs)
  File "/usr/local/lib/python3.8/_collections_abc.py", line 837, in update
    for key, value in other:
ValueError: not enough values to unpack (expected 2, got 1)
[2025-07-03T09:17:16.702+0000] {taskinstance.py:1138} INFO - Marking task as FAILED. dag_id=task_2_dagv01, task_id=extract, execution_date=20250703T091633, start_date=20250703T091716, end_date=20250703T091716
[2025-07-03T09:17:16.742+0000] {standard_task_runner.py:107} ERROR - Failed to execute job 4 for task extract (not enough values to unpack (expected 2, got 1); 298)
[2025-07-03T09:17:16.768+0000] {local_task_job_runner.py:234} INFO - Task exited with return code 1
[2025-07-03T09:17:16.791+0000] {taskinstance.py:3280} INFO - 0 downstream tasks scheduled from follow-on schedule check
