[2025-07-03T09:50:20.881+0000] {taskinstance.py:1956} INFO - Dependencies all met for dep_context=non-requeueable deps ti=<TaskInstance: task_2_dagv08.extract manual__2025-07-03T09:50:19.332148+00:00 [queued]>
[2025-07-03T09:50:20.891+0000] {taskinstance.py:1956} INFO - Dependencies all met for dep_context=requeueable deps ti=<TaskInstance: task_2_dagv08.extract manual__2025-07-03T09:50:19.332148+00:00 [queued]>
[2025-07-03T09:50:20.891+0000] {taskinstance.py:2170} INFO - Starting attempt 1 of 1
[2025-07-03T09:50:20.965+0000] {taskinstance.py:2191} INFO - Executing <Task(PythonOperator): extract> on 2025-07-03 09:50:19.332148+00:00
[2025-07-03T09:50:20.970+0000] {standard_task_runner.py:60} INFO - Started process 946 to run task
[2025-07-03T09:50:20.973+0000] {standard_task_runner.py:87} INFO - Running: ['airflow', 'tasks', 'run', 'task_2_dagv08', 'extract', 'manual__2025-07-03T09:50:19.332148+00:00', '--job-id', '14', '--raw', '--subdir', 'DAGS_FOLDER/task_2_dag.py', '--cfg-path', '/tmp/tmpcc9f7h3z']
[2025-07-03T09:50:20.974+0000] {standard_task_runner.py:88} INFO - Job 14: Subtask extract
[2025-07-03T09:50:21.028+0000] {logging_mixin.py:188} WARNING - /home/airflow/.local/lib/python3.8/site-packages/airflow/settings.py:194 DeprecationWarning: The sql_alchemy_conn option in [core] has been moved to the sql_alchemy_conn option in [database] - the old setting has been used, but please update your config.
[2025-07-03T09:50:21.071+0000] {task_command.py:423} INFO - Running <TaskInstance: task_2_dagv08.extract manual__2025-07-03T09:50:19.332148+00:00 [running]> on host b70660b8d774
[2025-07-03T09:50:21.259+0000] {taskinstance.py:2480} INFO - Exporting env vars: AIRFLOW_CTX_DAG_OWNER='airflow' AIRFLOW_CTX_DAG_ID='task_2_dagv08' AIRFLOW_CTX_TASK_ID='extract' AIRFLOW_CTX_EXECUTION_DATE='2025-07-03T09:50:19.332148+00:00' AIRFLOW_CTX_TRY_NUMBER='1' AIRFLOW_CTX_DAG_RUN_ID='manual__2025-07-03T09:50:19.332148+00:00'
[2025-07-03T09:50:22.477+0000] {taskinstance.py:2698} ERROR - Task failed with exception
Traceback (most recent call last):
  File "/home/airflow/.local/lib/python3.8/site-packages/airflow/models/taskinstance.py", line 433, in _execute_task
    result = execute_callable(context=context, **execute_callable_kwargs)
  File "/home/airflow/.local/lib/python3.8/site-packages/airflow/operators/python.py", line 199, in execute
    return_value = self.execute_callable()
  File "/home/airflow/.local/lib/python3.8/site-packages/airflow/operators/python.py", line 216, in execute_callable
    return self.python_callable(*self.op_args, **self.op_kwargs)
  File "/opt/airflow/Task_2/dag.py", line 7, in extract_data
    df.to_parquet(output_path)
  File "/home/airflow/.local/lib/python3.8/site-packages/pandas/core/frame.py", line 2889, in to_parquet
    return to_parquet(
  File "/home/airflow/.local/lib/python3.8/site-packages/pandas/io/parquet.py", line 411, in to_parquet
    impl.write(
  File "/home/airflow/.local/lib/python3.8/site-packages/pandas/io/parquet.py", line 161, in write
    path_or_handle, handles, kwargs["filesystem"] = _get_path_or_handle(
  File "/home/airflow/.local/lib/python3.8/site-packages/pandas/io/parquet.py", line 110, in _get_path_or_handle
    handles = get_handle(
  File "/home/airflow/.local/lib/python3.8/site-packages/pandas/io/common.py", line 868, in get_handle
    handle = open(handle, ioargs.mode)
PermissionError: [Errno 13] Permission denied: 'Task_2/Data/extracted.parquet'
[2025-07-03T09:50:22.524+0000] {taskinstance.py:1138} INFO - Marking task as FAILED. dag_id=task_2_dagv08, task_id=extract, execution_date=20250703T095019, start_date=20250703T095020, end_date=20250703T095022
[2025-07-03T09:50:22.587+0000] {standard_task_runner.py:107} ERROR - Failed to execute job 14 for task extract ([Errno 13] Permission denied: 'Task_2/Data/extracted.parquet'; 946)
[2025-07-03T09:50:22.603+0000] {local_task_job_runner.py:234} INFO - Task exited with return code 1
[2025-07-03T09:50:22.628+0000] {taskinstance.py:3280} INFO - 0 downstream tasks scheduled from follow-on schedule check
