[2025-07-03T09:24:31.028+0000] {taskinstance.py:1956} INFO - Dependencies all met for dep_context=non-requeueable deps ti=<TaskInstance: task_2_dagv01.transform manual__2025-07-03T09:23:59.084901+00:00 [queued]>
[2025-07-03T09:24:31.036+0000] {taskinstance.py:1956} INFO - Dependencies all met for dep_context=requeueable deps ti=<TaskInstance: task_2_dagv01.transform manual__2025-07-03T09:23:59.084901+00:00 [queued]>
[2025-07-03T09:24:31.037+0000] {taskinstance.py:2170} INFO - Starting attempt 1 of 1
[2025-07-03T09:24:31.108+0000] {taskinstance.py:2191} INFO - Executing <Task(PythonOperator): transform> on 2025-07-03 09:23:59.084901+00:00
[2025-07-03T09:24:31.115+0000] {standard_task_runner.py:60} INFO - Started process 448 to run task
[2025-07-03T09:24:31.118+0000] {standard_task_runner.py:87} INFO - Running: ['airflow', 'tasks', 'run', 'task_2_dagv01', 'transform', 'manual__2025-07-03T09:23:59.084901+00:00', '--job-id', '9', '--raw', '--subdir', 'DAGS_FOLDER/task_2_dag.py', '--cfg-path', '/tmp/tmpiqs8t3qo']
[2025-07-03T09:24:31.119+0000] {standard_task_runner.py:88} INFO - Job 9: Subtask transform
[2025-07-03T09:24:31.205+0000] {logging_mixin.py:188} WARNING - /home/airflow/.local/lib/python3.8/site-packages/airflow/settings.py:194 DeprecationWarning: The sql_alchemy_conn option in [core] has been moved to the sql_alchemy_conn option in [database] - the old setting has been used, but please update your config.
[2025-07-03T09:24:31.244+0000] {task_command.py:423} INFO - Running <TaskInstance: task_2_dagv01.transform manual__2025-07-03T09:23:59.084901+00:00 [running]> on host b70660b8d774
[2025-07-03T09:24:31.469+0000] {taskinstance.py:2480} INFO - Exporting env vars: AIRFLOW_CTX_DAG_OWNER='airflow' AIRFLOW_CTX_DAG_ID='task_2_dagv01' AIRFLOW_CTX_TASK_ID='transform' AIRFLOW_CTX_EXECUTION_DATE='2025-07-03T09:23:59.084901+00:00' AIRFLOW_CTX_TRY_NUMBER='1' AIRFLOW_CTX_DAG_RUN_ID='manual__2025-07-03T09:23:59.084901+00:00'
[2025-07-03T09:24:31.471+0000] {taskinstance.py:2698} ERROR - Task failed with exception
Traceback (most recent call last):
  File "/home/airflow/.local/lib/python3.8/site-packages/airflow/models/taskinstance.py", line 433, in _execute_task
    result = execute_callable(context=context, **execute_callable_kwargs)
  File "/home/airflow/.local/lib/python3.8/site-packages/airflow/operators/python.py", line 199, in execute
    return_value = self.execute_callable()
  File "/home/airflow/.local/lib/python3.8/site-packages/airflow/operators/python.py", line 216, in execute_callable
    return self.python_callable(*self.op_args, **self.op_kwargs)
TypeError: transform_data() missing 1 required positional argument: 'df'
[2025-07-03T09:24:31.516+0000] {taskinstance.py:1138} INFO - Marking task as FAILED. dag_id=task_2_dagv01, task_id=transform, execution_date=20250703T092359, start_date=20250703T092431, end_date=20250703T092431
[2025-07-03T09:24:31.604+0000] {standard_task_runner.py:107} ERROR - Failed to execute job 9 for task transform (transform_data() missing 1 required positional argument: 'df'; 448)
[2025-07-03T09:24:31.651+0000] {local_task_job_runner.py:234} INFO - Task exited with return code 1
[2025-07-03T09:24:31.679+0000] {taskinstance.py:3280} INFO - 0 downstream tasks scheduled from follow-on schedule check
