[2025-07-03T10:18:17.420+0000] {taskinstance.py:1956} INFO - Dependencies all met for dep_context=non-requeueable deps ti=<TaskInstance: task_2_dagv1.load manual__2025-07-03T10:17:38.375227+00:00 [queued]>
[2025-07-03T10:18:17.429+0000] {taskinstance.py:1956} INFO - Dependencies all met for dep_context=requeueable deps ti=<TaskInstance: task_2_dagv1.load manual__2025-07-03T10:17:38.375227+00:00 [queued]>
[2025-07-03T10:18:17.429+0000] {taskinstance.py:2170} INFO - Starting attempt 1 of 1
[2025-07-03T10:18:17.465+0000] {taskinstance.py:2191} INFO - Executing <Task(PythonOperator): load> on 2025-07-03 10:17:38.375227+00:00
[2025-07-03T10:18:17.472+0000] {standard_task_runner.py:60} INFO - Started process 275 to run task
[2025-07-03T10:18:17.475+0000] {standard_task_runner.py:87} INFO - Running: ['airflow', 'tasks', 'run', 'task_2_dagv1', 'load', 'manual__2025-07-03T10:17:38.375227+00:00', '--job-id', '4', '--raw', '--subdir', 'DAGS_FOLDER/task_2_dag.py', '--cfg-path', '/tmp/tmpzu0vucg4']
[2025-07-03T10:18:17.477+0000] {standard_task_runner.py:88} INFO - Job 4: Subtask load
[2025-07-03T10:18:17.518+0000] {logging_mixin.py:188} WARNING - /home/airflow/.local/lib/python3.8/site-packages/airflow/settings.py:194 DeprecationWarning: The sql_alchemy_conn option in [core] has been moved to the sql_alchemy_conn option in [database] - the old setting has been used, but please update your config.
[2025-07-03T10:18:17.577+0000] {task_command.py:423} INFO - Running <TaskInstance: task_2_dagv1.load manual__2025-07-03T10:17:38.375227+00:00 [running]> on host 86d79be21be1
[2025-07-03T10:18:17.758+0000] {taskinstance.py:2480} INFO - Exporting env vars: AIRFLOW_CTX_DAG_OWNER='airflow' AIRFLOW_CTX_DAG_ID='task_2_dagv1' AIRFLOW_CTX_TASK_ID='load' AIRFLOW_CTX_EXECUTION_DATE='2025-07-03T10:17:38.375227+00:00' AIRFLOW_CTX_TRY_NUMBER='1' AIRFLOW_CTX_DAG_RUN_ID='manual__2025-07-03T10:17:38.375227+00:00'
[2025-07-03T10:18:17.910+0000] {credentials.py:1147} INFO - Found credentials in environment variables.
[2025-07-03T10:18:20.749+0000] {taskinstance.py:2698} ERROR - Task failed with exception
Traceback (most recent call last):
  File "/home/airflow/.local/lib/python3.8/site-packages/boto3/s3/transfer.py", line 371, in upload_file
    future.result()
  File "/home/airflow/.local/lib/python3.8/site-packages/s3transfer/futures.py", line 103, in result
    return self._coordinator.result()
  File "/home/airflow/.local/lib/python3.8/site-packages/s3transfer/futures.py", line 266, in result
    raise self._exception
  File "/home/airflow/.local/lib/python3.8/site-packages/s3transfer/tasks.py", line 139, in __call__
    return self._execute_main(kwargs)
  File "/home/airflow/.local/lib/python3.8/site-packages/s3transfer/tasks.py", line 162, in _execute_main
    return_value = self._main(**kwargs)
  File "/home/airflow/.local/lib/python3.8/site-packages/s3transfer/tasks.py", line 348, in _main
    response = client.create_multipart_upload(
  File "/home/airflow/.local/lib/python3.8/site-packages/botocore/client.py", line 553, in _api_call
    return self._make_api_call(operation_name, kwargs)
  File "/home/airflow/.local/lib/python3.8/site-packages/botocore/client.py", line 1009, in _make_api_call
    raise error_class(parsed_response, operation_name)
botocore.errorfactory.NoSuchBucket: An error occurred (NoSuchBucket) when calling the CreateMultipartUpload operation: The specified bucket does not exist

During handling of the above exception, another exception occurred:

Traceback (most recent call last):
  File "/home/airflow/.local/lib/python3.8/site-packages/airflow/models/taskinstance.py", line 433, in _execute_task
    result = execute_callable(context=context, **execute_callable_kwargs)
  File "/home/airflow/.local/lib/python3.8/site-packages/airflow/operators/python.py", line 199, in execute
    return_value = self.execute_callable()
  File "/home/airflow/.local/lib/python3.8/site-packages/airflow/operators/python.py", line 216, in execute_callable
    return self.python_callable(*self.op_args, **self.op_kwargs)
  File "/opt/airflow/Task_2/dag.py", line 57, in load_to_s3
    s3.upload_file(file_path, bucket_name, s3_key)
  File "/home/airflow/.local/lib/python3.8/site-packages/boto3/s3/inject.py", line 145, in upload_file
    return transfer.upload_file(
  File "/home/airflow/.local/lib/python3.8/site-packages/boto3/s3/transfer.py", line 377, in upload_file
    raise S3UploadFailedError(
boto3.exceptions.S3UploadFailedError: Failed to upload Task_2/Data/transformed.parquet to twoj_bucket/twoj_klucz: An error occurred (NoSuchBucket) when calling the CreateMultipartUpload operation: The specified bucket does not exist
[2025-07-03T10:18:20.860+0000] {taskinstance.py:1138} INFO - Marking task as FAILED. dag_id=task_2_dagv1, task_id=load, execution_date=20250703T101738, start_date=20250703T101817, end_date=20250703T101820
[2025-07-03T10:18:20.939+0000] {standard_task_runner.py:107} ERROR - Failed to execute job 4 for task load (Failed to upload Task_2/Data/transformed.parquet to twoj_bucket/twoj_klucz: An error occurred (NoSuchBucket) when calling the CreateMultipartUpload operation: The specified bucket does not exist; 275)
[2025-07-03T10:18:20.980+0000] {local_task_job_runner.py:234} INFO - Task exited with return code 1
[2025-07-03T10:18:21.001+0000] {taskinstance.py:3280} INFO - 0 downstream tasks scheduled from follow-on schedule check
