[2025-07-03T09:28:55.832+0000] {taskinstance.py:1956} INFO - Dependencies all met for dep_context=non-requeueable deps ti=<TaskInstance: task_2_dagv06.transform manual__2025-07-03T09:28:30.126855+00:00 [queued]>
[2025-07-03T09:28:55.841+0000] {taskinstance.py:1956} INFO - Dependencies all met for dep_context=requeueable deps ti=<TaskInstance: task_2_dagv06.transform manual__2025-07-03T09:28:30.126855+00:00 [queued]>
[2025-07-03T09:28:55.841+0000] {taskinstance.py:2170} INFO - Starting attempt 1 of 1
[2025-07-03T09:28:55.958+0000] {taskinstance.py:2191} INFO - Executing <Task(PythonOperator): transform> on 2025-07-03 09:28:30.126855+00:00
[2025-07-03T09:28:55.965+0000] {standard_task_runner.py:60} INFO - Started process 616 to run task
[2025-07-03T09:28:55.969+0000] {standard_task_runner.py:87} INFO - Running: ['airflow', 'tasks', 'run', 'task_2_dagv06', 'transform', 'manual__2025-07-03T09:28:30.126855+00:00', '--job-id', '13', '--raw', '--subdir', 'DAGS_FOLDER/task_2_dag.py', '--cfg-path', '/tmp/tmp6t9u_22i']
[2025-07-03T09:28:55.971+0000] {standard_task_runner.py:88} INFO - Job 13: Subtask transform
[2025-07-03T09:28:56.014+0000] {logging_mixin.py:188} WARNING - /home/airflow/.local/lib/python3.8/site-packages/airflow/settings.py:194 DeprecationWarning: The sql_alchemy_conn option in [core] has been moved to the sql_alchemy_conn option in [database] - the old setting has been used, but please update your config.
[2025-07-03T09:28:56.056+0000] {task_command.py:423} INFO - Running <TaskInstance: task_2_dagv06.transform manual__2025-07-03T09:28:30.126855+00:00 [running]> on host b70660b8d774
[2025-07-03T09:28:56.256+0000] {taskinstance.py:2480} INFO - Exporting env vars: AIRFLOW_CTX_DAG_OWNER='airflow' AIRFLOW_CTX_DAG_ID='task_2_dagv06' AIRFLOW_CTX_TASK_ID='transform' AIRFLOW_CTX_EXECUTION_DATE='2025-07-03T09:28:30.126855+00:00' AIRFLOW_CTX_TRY_NUMBER='1' AIRFLOW_CTX_DAG_RUN_ID='manual__2025-07-03T09:28:30.126855+00:00'
[2025-07-03T09:28:56.257+0000] {taskinstance.py:2698} ERROR - Task failed with exception
Traceback (most recent call last):
  File "/home/airflow/.local/lib/python3.8/site-packages/airflow/models/taskinstance.py", line 433, in _execute_task
    result = execute_callable(context=context, **execute_callable_kwargs)
  File "/home/airflow/.local/lib/python3.8/site-packages/airflow/operators/python.py", line 199, in execute
    return_value = self.execute_callable()
  File "/home/airflow/.local/lib/python3.8/site-packages/airflow/operators/python.py", line 216, in execute_callable
    return self.python_callable(*self.op_args, **self.op_kwargs)
TypeError: transform_data() missing 1 required positional argument: 'df'
[2025-07-03T09:28:56.267+0000] {taskinstance.py:1138} INFO - Marking task as FAILED. dag_id=task_2_dagv06, task_id=transform, execution_date=20250703T092830, start_date=20250703T092855, end_date=20250703T092856
[2025-07-03T09:28:56.334+0000] {standard_task_runner.py:107} ERROR - Failed to execute job 13 for task transform (transform_data() missing 1 required positional argument: 'df'; 616)
[2025-07-03T09:28:56.382+0000] {local_task_job_runner.py:234} INFO - Task exited with return code 1
[2025-07-03T09:28:56.406+0000] {taskinstance.py:3280} INFO - 0 downstream tasks scheduled from follow-on schedule check
