[2025-07-03T09:21:51.713+0000] {taskinstance.py:1956} INFO - Dependencies all met for dep_context=non-requeueable deps ti=<TaskInstance: task_2_dagv02.extract manual__2025-07-03T09:21:50.326144+00:00 [queued]>
[2025-07-03T09:21:51.723+0000] {taskinstance.py:1956} INFO - Dependencies all met for dep_context=requeueable deps ti=<TaskInstance: task_2_dagv02.extract manual__2025-07-03T09:21:50.326144+00:00 [queued]>
[2025-07-03T09:21:51.724+0000] {taskinstance.py:2170} INFO - Starting attempt 1 of 1
[2025-07-03T09:21:51.782+0000] {taskinstance.py:2191} INFO - Executing <Task(PythonOperator): extract> on 2025-07-03 09:21:50.326144+00:00
[2025-07-03T09:21:51.787+0000] {standard_task_runner.py:60} INFO - Started process 364 to run task
[2025-07-03T09:21:51.790+0000] {standard_task_runner.py:87} INFO - Running: ['airflow', 'tasks', 'run', 'task_2_dagv02', 'extract', 'manual__2025-07-03T09:21:50.326144+00:00', '--job-id', '6', '--raw', '--subdir', 'DAGS_FOLDER/task_2_dag.py', '--cfg-path', '/tmp/tmp66x2dny6']
[2025-07-03T09:21:51.792+0000] {standard_task_runner.py:88} INFO - Job 6: Subtask extract
[2025-07-03T09:21:51.854+0000] {logging_mixin.py:188} WARNING - /home/airflow/.local/lib/python3.8/site-packages/airflow/settings.py:194 DeprecationWarning: The sql_alchemy_conn option in [core] has been moved to the sql_alchemy_conn option in [database] - the old setting has been used, but please update your config.
[2025-07-03T09:21:51.891+0000] {task_command.py:423} INFO - Running <TaskInstance: task_2_dagv02.extract manual__2025-07-03T09:21:50.326144+00:00 [running]> on host b70660b8d774
[2025-07-03T09:21:52.096+0000] {taskinstance.py:2480} INFO - Exporting env vars: AIRFLOW_CTX_DAG_OWNER='airflow' AIRFLOW_CTX_DAG_ID='task_2_dagv02' AIRFLOW_CTX_TASK_ID='extract' AIRFLOW_CTX_EXECUTION_DATE='2025-07-03T09:21:50.326144+00:00' AIRFLOW_CTX_TRY_NUMBER='1' AIRFLOW_CTX_DAG_RUN_ID='manual__2025-07-03T09:21:50.326144+00:00'
[2025-07-03T09:21:52.107+0000] {taskinstance.py:2698} ERROR - Task failed with exception
Traceback (most recent call last):
  File "/home/airflow/.local/lib/python3.8/site-packages/airflow/models/taskinstance.py", line 433, in _execute_task
    result = execute_callable(context=context, **execute_callable_kwargs)
  File "/home/airflow/.local/lib/python3.8/site-packages/airflow/operators/python.py", line 199, in execute
    return_value = self.execute_callable()
  File "/home/airflow/.local/lib/python3.8/site-packages/airflow/operators/python.py", line 216, in execute_callable
    return self.python_callable(*self.op_args, **self.op_kwargs)
  File "/opt/airflow/Task_2/dag.py", line 16, in extract_data
    df = pd.read_parquet(parquet_path, engine='pyarrow')
  File "/home/airflow/.local/lib/python3.8/site-packages/pandas/io/parquet.py", line 509, in read_parquet
    return impl.read(
  File "/home/airflow/.local/lib/python3.8/site-packages/pandas/io/parquet.py", line 220, in read
    path_or_handle, handles, kwargs["filesystem"] = _get_path_or_handle(
  File "/home/airflow/.local/lib/python3.8/site-packages/pandas/io/parquet.py", line 110, in _get_path_or_handle
    handles = get_handle(
  File "/home/airflow/.local/lib/python3.8/site-packages/pandas/io/common.py", line 868, in get_handle
    handle = open(handle, ioargs.mode)
FileNotFoundError: [Errno 2] No such file or directory: '/opt/airflow/dags/Task_2/Data/yellow_tripdata_2023-01.parquet'
[2025-07-03T09:21:52.118+0000] {taskinstance.py:1138} INFO - Marking task as FAILED. dag_id=task_2_dagv02, task_id=extract, execution_date=20250703T092150, start_date=20250703T092151, end_date=20250703T092152
[2025-07-03T09:21:52.176+0000] {standard_task_runner.py:107} ERROR - Failed to execute job 6 for task extract ([Errno 2] No such file or directory: '/opt/airflow/dags/Task_2/Data/yellow_tripdata_2023-01.parquet'; 364)
[2025-07-03T09:21:52.203+0000] {local_task_job_runner.py:234} INFO - Task exited with return code 1
[2025-07-03T09:21:52.230+0000] {taskinstance.py:3280} INFO - 0 downstream tasks scheduled from follow-on schedule check
